======================================================================
FAIL: test_works_in_mono_process_only_environment (tests.test_black.BlackTestCase)
----------------------------------------------------------------------
Traceback (most recent call last):
  File "/home/rowaha/.pyenv/versions/3.8.20/lib/python3.8/unittest/mock.py", line 1325, in patched
    return func(*newargs, **newkeywargs)
  File "/home/rowaha/work/llm-fl/BugsInPy/framework/bin/temp/black/tests/test_black.py", line 1288, in test_works_in_mono_process_only_environment
    self.invokeBlack([str(workspace)])
  File "/home/rowaha/work/llm-fl/BugsInPy/framework/bin/temp/black/tests/test_black.py", line 162, in invokeBlack
    self.assertEqual(result.exit_code, exit_code, msg=runner.stderr_bytes.decode())
AssertionError: 1 != 0 : 

----------------------------------------------------------------------
Ran 1 test in 0.028s

FAILED (failures=1)