=== Run starting ===


Agent updated: Fault Localizer Agent
Let's analyze the failing test andOPENAI_API_KEY is not set, skipping trace export
 trace the execution to localize the fault.

### Step 1: Analyze the Failing Test
The failing test is `test_get_foo` in `tests/test_foo.py`. The test asserts that the output of the function `bar()` should equal the input `'foo'`. However, the actual output is `'foo-2'`, which causes the assertion to fail.

### Step 2: Trace the Execution
1. **Test File (`tests/test_foo.py`)**:
   - The test calls `bar()` and expects the output to match the input `'foo'`.
   - The actual output is `'foo-2'`, which suggests that `bar()` is appending `'-2'` to the input.

2. **Function `bar()`**:
   - The test imports `bar` from somewhere. Since the executed files include `myproject/bar.py`, it is likely that `bar()` is defined there.

### Step 3: Locate the Definition of `bar()`
Let's inspect the content of `myproject/bar.py` to find the definition of `bar()`.OPENAI_API_KEY is not set, skipping trace export

-- Tool called: get_file_content, args: {"file_path":"myproject/bar.py","definitions":["bar"]}
-- Tool output: <file_content file_path="myproject/bar.py">
from myproject.x import foo

def bar():
    return foo()

</file_content>
OPENAI_API_KEY is not set, skipping trace export
The `bar()` function in `myproject/bar.py` calls another function `foo()` from `myproject.x` and returns its result. The output `'foo-2'` must be coming from `foo()`.

### Step 4: Locate the Definition of `foo()`
Now, let's inspect the content of `myproject/x.py` to find the definition of `foo()`.
-- Tool called: get_file_content, args: {"file_path":"myproject/x.py","definitions":["foo"]}
-- Tool output: <file_content file_path="myproject/x.py">
def foo():
    return "foo-2"

</file_content>
OPENAI_API_KEY is not set, skipping trace export
### Step 5: Analyze the Fault
- The function `foo()` in `myproject/x.py` returns the string `'foo-2'`.
- The test expects the output of `bar()` (which calls `foo()`) to be `'foo'`, but it gets `'foo-2'`.
- The fault lies in the implementation of `foo()`, which is hardcoded to return `'foo-2'` instead of the expected `'foo'`.

### Step 6: Conclusion
The fault is in `myproject/x.py`, where the function `foo()` returns `'foo-2'` instead of `'foo'`. To fix the test, `foo()` should be modified to return `'foo'` or the test should be updated to expect `'foo-2'` if that is the intended behavior. 

### Reasoning:
1. The test expects `bar()` to return `'foo'`.
2. `bar()` calls `foo()`, which returns `'foo-2'`.
3. The mismatch is due to the hardcoded return value in `foo()`.

### Suggested Fix:
- If `'foo'` is the correct output, modify `foo()` in `myproject/x.py` to return `'foo'`.
- If `'foo-2'` is the intended output, update the test to expect `'foo-2'`.

=== Run complete ===