======================================================================
FAIL: test_invalid_config_return_code (tests.test_black.BlackTestCase)
----------------------------------------------------------------------
Traceback (most recent call last):
  File "/home/rowaha/work/llm-fl/BugsInPy/framework/bin/temp/black/tests/test_black.py", line 1654, in test_invalid_config_return_code
    self.invokeBlack(args, exit_code=2, ignore_config=False)
  File "/home/rowaha/work/llm-fl/BugsInPy/framework/bin/temp/black/tests/test_black.py", line 162, in invokeBlack
    self.assertEqual(result.exit_code, exit_code, msg=runner.stderr_bytes.decode())
AssertionError: 1 != 2 : Error: Could not open file /tmp/blk_q97f8egz.log: Error reading configuration file: [Errno 2] No such file or directory: '/tmp/blk_q97f8egz.log'


----------------------------------------------------------------------
Ran 1 test in 0.007s

FAILED (failures=1)