======================================================================
ERROR: test_symlink_out_of_root_directory (tests.test_black.BlackTestCase)
----------------------------------------------------------------------
Traceback (most recent call last):
  File "/home/rowaha/work/llm-fl/BugsInPy/framework/bin/temp/black/tests/test_black.py", line 1183, in test_symlink_out_of_root_directory
    list(black.gen_python_files_in_dir(path, root, include, exclude, report))
  File "/home/rowaha/work/llm-fl/BugsInPy/framework/bin/temp/black/black.py", line 2948, in gen_python_files_in_dir
    normalized_path = "/" + child.resolve().relative_to(root).as_posix()
  File "/home/rowaha/.pyenv/versions/3.8.20/lib/python3.8/pathlib.py", line 908, in relative_to
    raise ValueError("{!r} does not start with {!r}"
ValueError: '/a/b/c' does not start with '/home/rowaha/work/llm-fl/BugsInPy/framework/bin/temp/black/tests'

----------------------------------------------------------------------
Ran 1 test in 0.003s

FAILED (errors=1)