=== Run starting ===


Agent updated: Fault Localizer Agent
OPENAI_API_KEY is not set, skipping trace export
To localize the fault, let's start by analyzing the failing test and the traceback:

1. **Failing Test**: The test `test_symlink_out_of_root_directory` in `tests/test_black.py` is failing.
2. **Error**: The error occurs in `black.gen_python_files_in_dir` when trying to resolve a path relative to a root directory. The error indicates that the path `/a/b/c` does not start with the expected root directory `/home/rowaha/work/llm-fl/BugsInPy/framework/bin/temp/black/tests`.

### Steps to Trace the Fault:

1. **Examine the Failing Test**:
   - The test is calling `black.gen_python_files_in_dir` with some arguments (`path`, `root`, `include`, `exclude`, `report`).
   - The error suggests that the `child` path resolved in `gen_python_files_in_dir` is not a subpath of the provided `root`.

2. **Trace the Function `gen_python_files_in_dir`**:
   - This function is defined in `black.py`.
   - The error occurs when calling `child.resolve().relative_to(root)`.

3. **Analyze the `gen_python_files_in_dir` Function**:
   - The function is likely iterating over files in a directory and resolving their paths relative to a root directory.
   - The error suggests that the function is not handling symlinks or paths outside the root directory correctly.

Let's first inspect the `gen_python_files_in_dir` function in `black.py`.
-- Tool called: get_function_body_tool, args: {"file_path":"black.py","function_name":"gen_python_files_in_dir"}
-- Tool output:
<function_body_with_coverage file_path=black.py>
> def gen_python_files_in_dir(
>     path: Path,
>     root: Path,
>     include: Pattern[str],
>     exclude: Pattern[str],
>     report: "Report",
> ) -> Iterator[Path]:
>     """Generate all files under `path` whose paths are not excluded by the
>     `exclude` regex, but are included by the `include` regex.

>     `report` is where output about exclusions goes.
>     """
>     assert root.is_absolute(), f"INTERNAL ERROR: `root` must be absolute but is {root}"   
>     for child in path.iterdir():
>         normalized_path = "/" + child.resolve().relative_to(root).as_posix()
!         if child.is_dir():
!             normalized_path += "/"
!         exclude_match = exclude.search(normalized_path)
!         if exclude_match and exclude_match.group(0):
!             report.path_ignored(child, f"matches the --exclude regular expression")       
!             continue

!         if child.is_dir():
!             yield from gen_python_files_in_dir(child, root, include, exclude, report)     

!         elif child.is_file():
!             include_match = include.search(normalized_path)
!             if include_match:
!                 yield child


<analysis>
- if the line begins with > then it was executed
- if the lines begins with ! then it was not executed
- if all the lines in the function begin with !, this funciton was never executed so ignore it
</analysis>

</function_body_with_coverage>

OPENAI_API_KEY is not set, skipping trace export
The fault occurs in the `gen_python_files_in_dir` function in `black.py`. Here's the analysis:

1. **Function Logic**:
   - The function iterates over files and directories under `path`.
   - For each `child`, it resolves the absolute path and then computes its relative path to `root` using `child.resolve().relative_to(root)`.
   - The error occurs because the resolved path of the `child` (`/a/b/c`) is not a subpath of the provided `root` (`/home/rowaha/work/llm-fl/BugsInPy/framework/bin/temp/black/tests`).

2. **Faulty Code Hunk**:
   - The line `normalized_path = "/" + child.resolve().relative_to(root).as_posix()` assumes that `child.resolve()` will always be a subpath of `root`. However, this is not true if `child` is a symlink pointing outside the `root` directory.

3. **Problem**:
   - The function does not handle cases where `child.resolve()` points outside the `root` directory. This leads to the `ValueError` when `relative_to` is called.

4. **Fix**:
   - The function should first check if the resolved path of `child` is within the `root` directory before calling `relative_to`. If not, it should skip or handle the symlink appropriately.

### Fault Localization:

name: `gen_python_files_in_dir`  
file: `black.py`  
explanation: The function assumes that all resolved paths of children are subpaths of the root directory, which is not true for symlinks pointing outside the root. This leads to a `ValueError` when `relative_to` is called. The function should validate the resolved path before attempting to compute the relative path.

=== Run complete ===

Main finished in 44.082 seconds
OPENAI_API_KEY is not set, skippin